Workbook

Sheet Apr 26
A1: Era | B1: Date Released | C1: Set Name | D1: BB Price (GBP) | E1: Set Value (GBP) | F1: Top 3 Chase Cards | G1: Box % | H1: Recommendation | I1: Chase Card % | J1: Print Status | K1: Decision Score | L1: Scarcity | M1: Liquidity | N1: Mascot Power | O1: Set Depth
A2: MEGA | B2: Mar-26 | C2: Perfect Order | D2: 169.22 | E2: 777.43 | F2: Mega Zygarde ex, Meowth ex, Mega Zygarde ex | G2: 0.2177 | H2: Accumulate | I2: 0.4645 | K2: 13 | L2: 2 | M2: 5 | N2: 3 | O2: 3
A3: MEGA | B3: 46023 | C3: Ascended Hereos | D3: 451.22 | E3: 1809.69 | F3: Mega Gengar ex, Pikachu ex, Mega Dragonite ex | G3: 0.2493 | H3: Accumulate | I3: 0.7517 | K3: 16 | L3: 2 | M3: 5 | N3: 4 | O3: 5
A4: MEGA | B4: 45962 | C4: Phantasmal Flames | D4: 372.79 | E4: 1044.44 | F4: Mega Charizard X ex, Mega Charizard X ex, Dawn | G4: 0.3569 | H4: Accumulate | I4: 0.8244 | K4: 17 | L4: 2 | M4: 5 | N4: 5 | O4: 5
A5: S&V | B5: 45901 | C5: Mega Evolution (Enhanced) | D5: 240.67 | E5: 1020.74 | F5: Mega Lucario ex, Mega Gardevoir ex, Mega Lucario ex | G5: 0.2358 | H5: Accumulate | I5: 0.4532 | K5: 15 | L5: 3 | M5: 5 | N5: 4 | O5: 3
A6: S&V | B6: 45839 | C6: Black Bolt | D6: 379.92 | E6: 1673.88 | F6: Victini, Zekrom ex, Zekrom ex | G6: 0.227 | H6: Accumulate | I6: 0.483 | K6: 13 | L6: 2 | M6: 5 | N6: 3 | O6: 3
A7: S&V | B7: 45839 | C7: White Flare | D7: 330.92 | E7: 1304.69 | F7: Reshiram ex, Reshiram ex, Hydreigon ex | G7: 0.2536 | H7: Accumulate | I7: 0.3471 | K7: 14 | L7: 2 | M7: 5 | N7: 4 | O7: 3
A8: S&V | B8: 45778 | C8: Destined Rivals | D8: 488.85 | E8: 1322.83 | F8: Team Rockets Mewtwo ex, Cynthias Garchomp ex, Ethans Ho Oh ex | G8: 0.3695 | H8: Accumulate | I8: 0.5115 | K8: 16 | L8: 2 | M8: 5 | N8: 4 | O8: 5
A9: S&V | B9: 45717 | C9: Journey Together (Enhanced) | D9: 225.62 | E9: 424.85 | F9: Lillies Clefairy ex, Salamence ex, Ns Zoroark ex | G9: 0.5311 | H9: Accumulate | I9: 0.4155 | K9: 15 | L9: 2 | M9: 5 | N9: 3 | O9: 5
A10: S&V | B10: 45658 | C10: Prismatic Evolutions | D10: 938.6 | E10: 3804.18 | F10: Umbreon ex, Sylveon ex, Leafeon ex | G10: 0.2467 | H10: Accumulate | I10: 0.4215 | K10: 17 | L10: 2 | M10: 5 | N10: 5 | O10: 5
A11: S&V | B11: 45597 | C11: Surging Sparks | D11: 244.38 | E11: 840.75 | F11: Pikachu ex, Latias ex, Milotic ex | G11: 0.2907 | H11: Accumulate | I11: 0.5111 | J11: In Print | K11: 13 | L11: 1 | M11: 5 | N11: 4 | O11: 3
A12: S&V | B12: 45536 | C12: Stellar Crown | D12: 263.22 | E12: 421.75 | F12: Squirtle, Bulbasaur, Dachsbun ex | G12: 0.6241 | H12: Accumulate | I12: 0.4862 | J12: In Print | K12: 12 | L12: 1 | M12: 5 | N12: 3 | O12: 3
A13: S&V | B13: 45505 | C13: Shrouded Fable | D13: 300.83 | E13: 376.39 | F13: Duskull, Persian, Dusclops | G13: 0.7993 | H13: Hold | I13: 0.2859 | J13: In Print | K13: 11 | L13: 1 | M13: 5 | N13: 2 | O13: 3
A14: S&V | B14: 45413 | C14: Twilight Masquerade | D14: 296.06 | E14: 936.68 | F14: Greninja ex, Perrin, Eevee | G14: 0.3161 | H14: Accumulate | I14: 0.4594 | J14: In Print | K14: 14 | L14: 2 | M14: 5 | N14: 4 | O14: 3
A15: S&V | B15: 45352 | C15: Temporal Forces | D15: 244.43 | E15: 726.76 | F15: Gastly, Mortys Conviction, Raging Bolt ex | G15: 0.3363 | H15: Accumulate | I15: 0.2389 | J15: In Print | K15: 12 | L15: 1 | M15: 5 | N15: 3 | O15: 3
A16: S&V | B16: 45292 | C16: Paldean Fates | D16: 1470.72 | E16: 1590.39 | F16: Mew ex, Charizard ex, Gardevoir ex | G16: 0.9248 | H16: Accumulate | I16: 0.587 | J16: Printing Till Sprint 2026 | K16: 17 | L16: 2 | M16: 5 | N16: 5 | O16: 5
A17: S&V | B17: 45231 | C17: Paradox Rift | D17: 225.63 | E17: 732.98 | F17: Groudon, Altaria ex, Plusle | G17: 0.3078 | H17: Accumulate | I17: 0.1994 | J17: Printing Till Sprint 2026 | K17: 13 | L17: 2 | M17: 5 | N17: 3 | O17: 3
A18: S&V | B18: 45170 | C18: 151 | D18: 2214.14 | E18: 1723.88 | F18: Charizard ex, Blastoise ex, Venusaur ex | G18: 1.2844 | H18: Accumulate | I18: 0.3087 | J18: Printing Till Sprint 2026 | K18: 17 | L18: 2 | M18: 5 | N18: 5 | O18: 5
A19: S&V | B19: 45139 | C19: Obsidian Flames | D19: 310.23 | E19: 382.35 | F19: Charizard ex, Cleffa, Charizard ex | G19: 0.8114 | H19: Accumulate | I19: 0.3987 | J19: Printing Till Sprint 2026 | K19: 17 | L19: 2 | M19: 5 | N19: 5 | O19: 5
A20: S&V | B20: 45078 | C20: Paldea Evolved | D20: 376.04 | E20: 1234.73 | F20: Magikarp, Raichu, Maushold | G20: 0.3046 | H20: Accumulate | I20: 0.312 | J20: Printing Till Sprint 2026 | K20: 13 | L20: 2 | M20: 5 | N20: 3 | O20: 3
A21: S&V | B21: 44986 | C21: S&V Base set | D21: 225.62 | E21: 555.26 | F21: Gardevoir ex, Drowzee, Kirlia | G21: 0.4063 | H21: Accumulate | I21: 0.2452 | J21: Printing Till Sprint 2026 | K21: 13 | L21: 2 | M21: 5 | N21: 3 | O21: 3
A22: SWSH | B22: 44927 | C22: Crown Zenith | D22: 1052.92 | E22: 1633.14 | F22: Mewtwo VSTAR, Giratina VSTAR Secret, Arceus VSTAR Secret | G22: 0.6447 | H22: Strong Buy | I22: 0.2856 | K22: 19 | L22: 5 | M22: 5 | N22: 4 | O22: 5
A23: SWSH | B23: 44866 | C23: Silver Tempest | D23: 413.65 | E23: 896.32 | F23: Lugia V Alternate Full Art, Rayquaza VMAX, Lugia VSTAR Secret 202 | G23: 0.4615 | H23: Buy | I23: 0.4687 | K23: 18 | L23: 4 | M23: 5 | N23: 4 | O23: 5
A24: SWSH | B24: 44805 | C24: Lost Origin | D24: 676.87 | E24: 1250.59 | F24: Giratina V Alternate Full Art, Aerodactyl V Alternate Full Art, Pikachu VMAX | G24: 0.5412 | H24: Strong Buy | I24: 0.5722 | K24: 19 | L24: 5 | M24: 5 | N24: 4 | O24: 5
A25: SWSH | B25: 44682 | C25: Astral Radiance | D25: 364.76 | E25: 834.23 | F25: Machamp V Alternate Full Art, Origin Forme Palkia V Alternate Full Art, Origin Forme Dialga V Alternate Full Art | G25: 0.4372 | H25: Buy | I25: 0.2719 | K25: 17 | L25: 4 | M25: 5 | N25: 3 | O25: 5
A26: SWSH | B26: 44593 | C26: Brilliant Stars | D26: 526.46 | E26: 988.52 | F26: Charizard V Alternate Full Art, Umbreon VMAX, Charizard VSTAR Secret | G26: 0.5326 | H26: Strong Buy | I26: 0.3547 | K26: 20 | L26: 5 | M26: 5 | N26: 5 | O26: 5
A27: SWSH | B27: 44501 | C27: Fusion Strike | D27: 902.46 | E27: 1467.45 | F27: Gengar VMAX Alternate Art Secret, Espeon VMAX Alternate Art Secret, Mew VMAX Alternate Art Secret | G27: 0.615 | H27: Strong Buy | I27: 0.6629 | K27: 19 | L27: 5 | M27: 5 | N27: 4 | O27: 5
A28: SWSH | B28: 44470 | C28: Celebrations 25th | D28: 1263.47 | E28: 474.02 | F28: Charizard, Umbreon Star, Mew Secret | G28: 2.6654 | H28: Strong Buy | I28: 0.5408 | K28: 19 | L28: 4 | M28: 5 | N28: 5 | O28: 5
A29: SWSH | B29: 44409 | C29: Evolving Skies | D29: 2619.13 | E29: 4759.5 | F29: Umbreon VMAX Alternate Art Secret, Rayquaza VMAX Alternate Art Secret, Dragonite V Alternate Full Art | G29: 0.5503 | H29: Buy | I29: 0.476 | J29: Long-Term OOP | K29: 19 | L29: 4 | M29: 5 | N29: 5 | O29: 5
A30: SWSH | B30: 44348 | C30: Chilling Reign | D30: 451.25 | E30: 1294.81 | F30: Blaziken VMAX Alternate Art Secret, Galarian Moltres V Alternate Full Art, Snorlax Secret | G30: 0.3485 | H30: Buy | I30: 0.3768 | K30: 17 | L30: 4 | M30: 5 | N30: 3 | O30: 5
A31: SWSH | B31: 44256 | C31: Battle Styles | D31: 225.63 | E31: 570.76 | F31: Tyranitar V Alternate Full Art, Rapid Strike Urshifu VMAX Alternate Art Secret, Empoleon V Alternate Full Art | G31: 0.3953 | H31: Buy | I31: 0.4807 | K31: 17 | L31: 4 | M31: 5 | N31: 3 | O31: 5
A32: SWSH | B32: 44228 | C32: Shining Fates | D32: 451.25 | E32: 463.28 | F32: Charizard VMAX, Skyla Full Art, Suicune | G32: 0.974 | H32: Strong Buy | I32: 0.2818 | K32: 19 | L32: 4 | M32: 5 | N32: 5 | O32: 5
A33: SWSH | B33: 44136 | C33: Vivid Voltage | D33: 259.47 | E33: 381.42 | F33: Pikachu VMAX Secret, Pikachu V Full Art, Pokemon Center Lady Full Art | G33: 0.6803 | H33: Strong Buy | I33: 0.4062 | K33: 19 | L33: 4 | M33: 5 | N33: 5 | O33: 5
A34: SWSH | B34: 44075 | C34: Champions Path | D34: 601.64 | E34: 379.49 | F34: Charizard V Secret, Charizard VMAX Secret, Gardevoir VMAX Secret | G34: 1.5854 | H34: Strong Buy | I34: 0.8584 | K34: 19 | L34: 4 | M34: 5 | N34: 5 | O34: 5
A35: SWSH | B35: 44044 | C35: Darkness Ablaze | D35: 298.92 | E35: 215.13 | F35: Charizard VMAX, Butterfree VMAX Secret, Salamence VMAX Secret | G35: 1.3895 | H35: Strong Buy | I35: 0.2615 | K35: 19 | L35: 4 | M35: 5 | N35: 5 | O35: 5
A36: SWSH | B36: 43952 | C36: Rebel Clash | D36: 575.34 | E36: 373.47 | F36: Bosss Orders Full Art, Bosss Orders Secret, Ninetales V Full Art | G36: 1.5405 | H36: Buy | I36: 0.2399 | K36: 15 | L36: 4 | M36: 5 | N36: 3 | O36: 3
A37: SWSH | B37: 43862 | C37: Sword and Shield | D37: 592.64 | E37: 395.38 | F37: Snorlax VMAX Secret, Snorlax VMAX, Marnie Full Art | G37: 1.4989 | H37: Buy | I37: 0.3158 | K37: 15 | L37: 4 | M37: 5 | N37: 3 | O37: 3
A38: SM | B38: 43770 | C38: Cosmic Eclipse | D38: 5264.58 | E38: 4131.82 | F38: Arceus and Dialga and Palkia GX Alternate Art, Reshiram and Zekrom GX Full Art, Blastoise and Piplup GX Alternate Art | G38: 1.2742 | H38: Buy | I38: 0.2265 | K38: 18 | L38: 4 | M38: 5 | N38: 4 | O38: 5
A39: SM | B39: 43678 | C39: Hidden Fates | D39: 1955.42 | E39: 2179.83 | F39: Umbreon GX, Sylveon GX, Cynthia | G39: 0.8971 | H39: Hold | I39: 0.1902 | K39: 18 | L39: 3 | M39: 5 | N39: 5 | O39: 5
A40: SM | B40: 43678 | C40: Unified Minds | D40: 3758.88 | E40: 3000.12 | F40: Mewtwo and Mew GX Secret, Mega Sableye and Tyranitar GX Alternate Art, Raichu and Alolan Raichu GX Alternate Full Art | G40: 1.2529 | H40: Buy | I40: 0.2566 | K40: 18 | L40: 4 | M40: 5 | N40: 4 | O40: 5
...

Sheet Mar 26
A1: Era | B1: Date Released | C1: Set Name | D1: BB Price - Or 6 Booster Equivalent? | E1: Set Value (GBP) | F1: Top 3 Chase Cards | G1: Box % of Set (Sort By Ascending) | H1: Investor Rating | I1: Chase Card % (Risk) | J1: Print Status | K1: Decision Matrix | L1: Scarcity (Print Status) | M1: Format Liquidity | N1: Mascot Power | O1: Set Depth
A2: S&V | B2: 45658 | C2: Prismatic Evolutions | D2: 280 | E2: 4161 | F2: 1655 | G2: ='Mar 26'!$D2/E2 -> 0.067291516 | I2: ='Mar 26'!$F2/'Mar 26'!$E2 -> 0.39774093 | K2: =SUM('Mar 26'!$L2:$O2) -> 14 | L2: 2 | M2: 2 | N2: 5 | O2: 5
A3: MEGA | B3: 46023 | C3: Ascended Hereos | D3: 280 | E3: 2279 | F3: 1593 | G3: ='Mar 26'!$D3/E3 -> 0.1228609 | I3: ='Mar 26'!$F3/'Mar 26'!$E3 -> 0.69899079 | K3: =SUM('Mar 26'!$L3:$O3) -> 15 | L3: 3 | M3: 2 | N3: 5 | O3: 5
A4: S&V | B4: 45839 | C4: Black Bolt | D4: 300 | E4: 1980 | F4: 843 | G4: ='Mar 26'!$D4/E4 -> 0.15151515 | I4: ='Mar 26'!$F4/'Mar 26'!$E4 -> 0.42575758 | K4: =SUM('Mar 26'!$L4:$O4) -> 1 | L4: 1
A5: S&V | B5: 45839 | C5: White Flare | D5: 312 | E5: 1554 | F5: 568 | G5: ='Mar 26'!$D5/E5 -> 0.2007722 | I5: ='Mar 26'!$F5/'Mar 26'!$E5 -> 0.36550837 | K5: =SUM('Mar 26'!$L5:$O5) -> 1 | L5: 1
A6: S&V | B6: 45901 | C6: Mega Evolution (Enhanced) | D6: 270 | E6: 1325 | F6: 618 | G6: ='Mar 26'!$D6/E6 -> 0.20377358 | H6: STRONG BUY (Deep Value) | I6: ='Mar 26'!$F6/'Mar 26'!$E6 -> 0.46641509 | K6: =SUM('Mar 26'!$L6:$O6) -> 1 | L6: 1
A7: SWSH | B7: 44866 | C7: Silver Tempest | D7: 260 | E7: 1030 | F7: 481 | G7: ='Mar 26'!$D7/E7 -> 0.25242718 | I7: ='Mar 26'!$F7/'Mar 26'!$E7 -> 0.46699029 | K7: =SUM('Mar 26'!$L7:$O7) -> 0
A8: Mega | B8: 45962 | C8: Phantasmal Flames | D8: 327 | E8: 1264 | F8: 1077 | G8: ='Mar 26'!$D8/E8 -> 0.25870253 | H8: Speculative Play | I8: ='Mar 26'!$F8/'Mar 26'!$E8 -> 0.85205696 | K8: =SUM('Mar 26'!$L8:$O8) -> 1 | L8: 1
A9: S&V | B9: 45597 | C9: Surging Sparks | D9: 267 | E9: 1012 | F9: 509 | G9: ='Mar 26'!$D9/E9 -> 0.26383399 | H9: Buy on Dips | I9: ='Mar 26'!$F9/'Mar 26'!$E9 -> 0.50296443 | J9: In Print | K9: =SUM('Mar 26'!$L9:$O9) -> 3 | L9: 3
A10: S&V | B10: 45231 | C10: Paradox Rift | D10: 250 | E10: 845 | F10: 148 | G10: ='Mar 26'!$D10/E10 -> 0.29585799 | H10: Value Sleeper | I10: ='Mar 26'!$F10/'Mar 26'!$E10 -> 0.17514793 | J10: Printing Till Sprint 2026 | K10: =SUM('Mar 26'!$L10:$O10) -> 4 | L10: 4
A11: SWSH | B11: 44348 | C11: Chilling Reign | D11: 501 | E11: 1656 | F11: 641 | G11: ='Mar 26'!$D11/E11 -> 0.30253623 | H11: Fair Value | I11: ='Mar 26'!$F11/'Mar 26'!$E11 -> 0.38707729 | K11: =SUM('Mar 26'!$L11:$O11) -> 0
A12: S&V | B12: 45078 | C12: Paldea Evolved | D12: 419 | E12: 1366 | F12: 418 | G12: ='Mar 26'!$D12/E12 -> 0.30673499 | I12: ='Mar 26'!$F12/'Mar 26'!$E12 -> 0.30600293 | J12: Printing Till Sprint 2026 | K12: =SUM('Mar 26'!$L12:$O12) -> 4 | L12: 4
A13: S&V | B13: 45352 | C13: Temporal Forces | D13: 250 | E13: 810 | F13: 152 | G13: ='Mar 26'!$D13/E13 -> 0.30864198 | I13: ='Mar 26'!$F13/'Mar 26'!$E13 -> 0.18765432 | J13: In Print | K13: =SUM('Mar 26'!$L13:$O13) -> 4 | L13: 4
A14: S&V | B14: 45413 | C14: Twilight Masquerade | D14: 320 | E14: 1011 | F14: 402 | G14: ='Mar 26'!$D14/E14 -> 0.3165183 | H14: Neutral | I14: ='Mar 26'!$F14/'Mar 26'!$E14 -> 0.39762611 | J14: In Print | K14: =SUM('Mar 26'!$L14:$O14) -> 2 | L14: 2
A15: S&V | B15: 45778 | C15: Destined Rivals | D15: 510 | E15: 1558 | F15: 813 | G15: ='Mar 26'!$D15/E15 -> 0.32734275 | H15: ACCUMULATE | I15: ='Mar 26'!$F15/'Mar 26'!$E15 -> 0.52182285 | K15: =SUM('Mar 26'!$L15:$O15) -> 19 | L15: 4 | M15: 5 | N15: 5 | O15: 5
A16: SWSH | B16: 44256 | C16: Battle Styles | D16: 240 | E16: 694 | F16: 325 | G16: ='Mar 26'!$D16/E16 -> 0.34582133 | I16: ='Mar 26'!$F16/'Mar 26'!$E16 -> 0.46829971 | K16: =SUM('Mar 26'!$L16:$O16) -> 0
A17: SWSH | B17: 44682 | C17: Astral Radiance | D17: 390 | E17: 1000 | F17: 321 | G17: ='Mar 26'!$D17/E17 -> 0.39 | I17: ='Mar 26'!$F17/'Mar 26'!$E17 -> 0.321 | K17: =SUM('Mar 26'!$L17:$O17) -> 0
A18: S&V | B18: 44986 | C18: S&V Base set | D18: 255 | E18: 609 | F18: 130 | G18: ='Mar 26'!$D18/E18 -> 0.41871921 | I18: ='Mar 26'!$F18/'Mar 26'!$E18 -> 0.2134647 | J18: Printing Till Sprint 2026 | K18: =SUM('Mar 26'!$L18:$O18) -> 0
A19: SWSH | B19: 44409 | C19: Evolving Skies | D19: 2500 | E19: 5846 | F19: 2737 | G19: ='Mar 26'!$D19/E19 -> 0.42764283 | H19: BLUE CHIP (Core Hold) | I19: ='Mar 26'!$F19/'Mar 26'!$E19 -> 0.46818337 | J19: Long-Term OOP | K19: =SUM('Mar 26'!$L19:$O19) -> 20 | L19: 5 | M19: 5 | N19: 5 | O19: 5
A20: S&V | B20: 45717 | C20: Journey Together (Enhanced) | D20: 252 | E20: 541 | F20: 232 | G20: ='Mar 26'!$D20/E20 -> 0.46580407 | I20: ='Mar 26'!$F20/'Mar 26'!$E20 -> 0.42883549 | K20: =SUM('Mar 26'!$L20:$O20) -> 0
A21: SWSH | B21: 44805 | C21: Lost Origin | D21: 733 | E21: 1500 | F21: 933 | G21: ='Mar 26'!$D21/E21 -> 0.48866667 | I21: ='Mar 26'!$F21/'Mar 26'!$E21 -> 0.622 | K21: =SUM('Mar 26'!$L21:$O21) -> 0
A22: S&V | B22: 45170 | C22: 151 | D22: 780 | E22: 1530 | F22: 633 | G22: ='Mar 26'!$D22/E22 -> 0.50980392 | I22: ='Mar 26'!$F22/'Mar 26'!$E22 -> 0.41372549 | J22: Printing Till Sprint 2026 | K22: =SUM('Mar 26'!$L22:$O22) -> 0
A23: SWSH | B23: 44593 | C23: Brilliant Stars | D23: 580 | E23: 1100 | F23: 371 | G23: ='Mar 26'!$D23/E23 -> 0.52727273 | I23: ='Mar 26'!$F23/'Mar 26'!$E23 -> 0.33727273 | K23: =SUM('Mar 26'!$L23:$O23) -> 0
A24: S&V | B24: 45292 | C24: Paldean Fates | D24: 800 | E24: 1513 | F24: 798 | G24: ='Mar 26'!$D24/E24 -> 0.52875083 | I24: ='Mar 26'!$F24/'Mar 26'!$E24 -> 0.52742895 | J24: Printing Till Sprint 2026 | K24: =SUM('Mar 26'!$L24:$O24) -> 0
A25: S&V | B25: 45505 | C25: Shrouded Fable | D25: 240 | E25: 434 | F25: 124 | G25: ='Mar 26'!$D25/E25 -> 0.55299539 | I25: ='Mar 26'!$F25/'Mar 26'!$E25 -> 0.28571429 | J25: In Print | K25: =SUM('Mar 26'!$L25:$O25) -> 0
A26: SWSH | B26: 44501 | C26: Fusion Strike | D26: 1005 | E26: 1776 | F26: 1205 | G26: ='Mar 26'!$D26/E26 -> 0.56587838 | H26: Hold / Take Profits | I26: ='Mar 26'!$F26/'Mar 26'!$E26 -> 0.67849099 | K26: =SUM('Mar 26'!$L26:$O26) -> 0
A27: SWSH | B27: 44136 | C27: Vivid Voltage | D27: 280 | E27: 470 | F27: 190 | G27: ='Mar 26'!$D27/E27 -> 0.59574468 | I27: ='Mar 26'!$F27/'Mar 26'!$E27 -> 0.40425532 | K27: =SUM('Mar 26'!$L27:$O27) -> 14 | L27: 5 | M27: 5 | N27: 3 | O27: 1
A28: SWSH | B28: 44927 | C28: Crown Zenith | D28: 1140 | E28: 1750 | F28: 524 | G28: ='Mar 26'!$D28/E28 -> 0.65142857 | I28: ='Mar 26'!$F28/'Mar 26'!$E28 -> 0.29942857 | K28: =SUM('Mar 26'!$L28:$O28) -> 0
A29: S&M | B29: 43678 | C29: Hidden Fates | D29: 1800 | E29: 2700 | F29: 947 | G29: ='Mar 26'!$D29/E29 -> 0.66666667 | I29: ='Mar 26'!$F29/'Mar 26'!$E29 -> 0.35074074 | K29: =SUM('Mar 26'!$L29:$O29) -> 0
A30: S&V | B30: 45536 | C30: Stellar Crown | D30: 290 | E30: 420 | F30: 176 | G30: ='Mar 26'!$D30/E30 -> 0.69047619 | H30: Overvalued (Avoid) | I30: ='Mar 26'!$F30/'Mar 26'!$E30 -> 0.41904762 | J30: In Print | K30: =SUM('Mar 26'!$L30:$O30) -> 0
A31: S&M | B31: 43770 | C31: Cosmic Eclipse | D31: 3829 | E31: 5371 | F31: 1259 | G31: ='Mar 26'!$D31/E31 -> 0.71290263 | H31: Mature / Hold | I31: ='Mar 26'!$F31/'Mar 26'!$E31 -> 0.234407 | K31: =SUM('Mar 26'!$L31:$O31) -> 0
A32: S&M | B32: 43405 | C32: Lost Thunder | D32: 1757 | E32: 2273 | F32: 551 | G32: ='Mar 26'!$D32/E32 -> 0.77298724 | I32: ='Mar 26'!$F32/'Mar 26'!$E32 -> 0.24241091 | K32: =SUM('Mar 26'!$L32:$O32) -> 0
A33: S&M | B33: 43586 | C33: Unbroken Bonds | D33: 2658 | E33: 3435 | F33: 1054 | G33: ='Mar 26'!$D33/E33 -> 0.77379913 | I33: ='Mar 26'!$F33/'Mar 26'!$E33 -> 0.30684134 | K33: =SUM('Mar 26'!$L33:$O33) -> 0
A34: S&V | B34: 45139 | C34: Obsidian Flames | D34: 300 | E34: 382 | F34: 146 | G34: ='Mar 26'!$D34/E34 -> 0.78534031 | H34: AVOID (Peak Hype) | I34: ='Mar 26'!$F34/'Mar 26'!$E34 -> 0.38219895 | J34: Printing Till Sprint 2026 | K34: =SUM('Mar 26'!$L34:$O34) -> 0
A35: S&M | B35: 43678 | C35: Unified Minds | D35: 3111 | E35: 3846 | F35: 1009 | G35: ='Mar 26'!$D35/E35 -> 0.80889236 | I35: ='Mar 26'!$F35/'Mar 26'!$E35 -> 0.26235049 | K35: =SUM('Mar 26'!$L35:$O35) -> 0
A36: S&M | B36: 43132 | C36: Ultra Prism | D36: 1671 | E36: 2002 | F36: 802 | G36: ='Mar 26'!$D36/E36 -> 0.83466533 | H36: Mature / Hold | I36: ='Mar 26'!$F36/'Mar 26'!$E36 -> 0.4005994 | K36: =SUM('Mar 26'!$L36:$O36) -> 0
A37: SWSH | B37: 44228 | C37: Shining Fates | D37: 456 | E37: 500 | F37: 152 | G37: ='Mar 26'!$D37/E37 -> 0.912 | I37: ='Mar 26'!$F37/'Mar 26'!$E37 -> 0.304 | K37: =SUM('Mar 26'!$L37:$O37) -> 0
A38: SWSH | B38: 43952 | C38: Rebel Clash | D38: 497 | E38: 478 | F38: 115 | G38: ='Mar 26'!$D38/E38 -> 1.039749 | I38: ='Mar 26'!$F38/'Mar 26'!$E38 -> 0.24058577 | K38: =SUM('Mar 26'!$L38:$O38) -> 0
A39: SWSH | B39: 44075 | C39: Champions Path | D39: 612 | E39: 521 | F39: 454 | G39: ='Mar 26'!$D39/E39 -> 1.1746641 | I39: ='Mar 26'!$F39/'Mar 26'!$E39 -> 0.87140115 | K39: =SUM('Mar 26'!$L39:$O39) -> 0
A40: SWSH | B40: 44044 | C40: Darkness Ablaze | D40: 324 | E40: 270 | F40: 70 | G40: ='Mar 26'!$D40/E40 -> 1.2 | I40: ='Mar 26'!$F40/'Mar 26'!$E40 -> 0.25925926 | K40: =SUM('Mar 26'!$L40:$O40) -> 0
...

Sheet Feb 26
A1: Era | B1: Date Released | C1: Set Name | D1: BB Price - Or 4 Booster Equivalent? | E1: Set Value (GBP) | F1: Top 3 Chase Cards | G1: Box % of Set (Sort By Ascending) | H1: Investor Rating | I1: Chase Card % (Risk) | J1: Print Status | K1: Decision Matrix | L1: Scarcity (Print Status) | M1: Format Liquidity | N1: Mascot Power | O1: Set Depth
A2: SWSH | B2: 42675 | C2: Evolutions | D2: 1314 | E2: 603 | F2: 174.5 | G2: ='Feb 26'!$D2/E2 -> 2.1791045 | I2: ='Feb 26'!$F2/'Feb 26'!$E2 -> 0.2893864 | K2: =SUM('Feb 26'!$L2:$O2) -> 0
A3: S&M | B3: 43132 | C3: Ultra Prism | D3: 1200 | E3: 1550 | F3: 603 | G3: ='Feb 26'!$D3/E3 -> 0.77419355 | H3: Mature / Hold | I3: ='Feb 26'!$F3/'Feb 26'!$E3 -> 0.38903226 | K3: =SUM('Feb 26'!$L3:$O3) -> 0
A4: S&M | B4: 43405 | C4: Lost Thunder | D4: 1177 | E4: 1654 | F4: 400 | G4: ='Feb 26'!$D4/E4 -> 0.71160822 | I4: ='Feb 26'!$F4/'Feb 26'!$E4 -> 0.24183797 | K4: =SUM('Feb 26'!$L4:$O4) -> 0
A5: S&M | B5: 43497 | C5: Team Up | D5: 7500 | E5: 7100 | F5: 3683 | G5: ='Feb 26'!$D5/E5 -> 1.056338 | H5: BUBBLE (Sell/Trim) | I5: ='Feb 26'!$F5/'Feb 26'!$E5 -> 0.51873239 | K5: =SUM('Feb 26'!$L5:$O5) -> 0
A6: S&M | B6: 43586 | C6: Unbroken Bonds | D6: 1957 | E6: 2518 | F6: 767 | G6: ='Feb 26'!$D6/E6 -> 0.77720413 | I6: ='Feb 26'!$F6/'Feb 26'!$E6 -> 0.30460683 | K6: =SUM('Feb 26'!$L6:$O6) -> 0
A7: S&M | B7: 43678 | C7: Unified Minds | D7: 2329 | E7: 2847 | F7: 742 | G7: ='Feb 26'!$D7/E7 -> 0.81805409 | I7: ='Feb 26'!$F7/'Feb 26'!$E7 -> 0.26062522 | K7: =SUM('Feb 26'!$L7:$O7) -> 0
A8: S&M | B8: 43678 | C8: Hidden Fates | D8: 2000 | E8: 1811 | F8: 925 | G8: ='Feb 26'!$D8/E8 -> 1.1043622 | I8: ='Feb 26'!$F8/'Feb 26'!$E8 -> 0.51076753 | K8: =SUM('Feb 26'!$L8:$O8) -> 0
A9: S&M | B9: 43770 | C9: Cosmic Eclipse | D9: 3150 | E9: 4200 | F9: 916 | G9: ='Feb 26'!$D9/E9 -> 0.75 | H9: Mature / Hold | I9: ='Feb 26'!$F9/'Feb 26'!$E9 -> 0.21809524 | K9: =SUM('Feb 26'!$L9:$O9) -> 0
A10: SWSH | B10: 43952 | C10: Rebel Clash | D10: 590 | E10: 478 | F10: 110 | G10: ='Feb 26'!$D10/E10 -> 1.2343096 | I10: ='Feb 26'!$F10/'Feb 26'!$E10 -> 0.23012552 | K10: =SUM('Feb 26'!$L10:$O10) -> 0
A11: SWSH | B11: 44044 | C11: Darkness Ablaze | D11: 240 | E11: 193 | F11: 50 | G11: ='Feb 26'!$D11/E11 -> 1.2435233 | I11: ='Feb 26'!$F11/'Feb 26'!$E11 -> 0.25906736 | K11: =SUM('Feb 26'!$L11:$O11) -> 0
A12: SWSH | B12: 44075 | C12: Champions Path | D12: 800 | E12: 385 | F12: 454 | G12: ='Feb 26'!$D12/E12 -> 2.0779221 | I12: ='Feb 26'!$F12/'Feb 26'!$E12 -> 1.1792208 | K12: =SUM('Feb 26'!$L12:$O12) -> 0
A13: SWSH | B13: 44136 | C13: Vivid Voltage | D13: 195 | E13: 333 | F13: 138 | G13: ='Feb 26'!$D13/E13 -> 0.58558559 | I13: ='Feb 26'!$F13/'Feb 26'!$E13 -> 0.41441441 | K13: =SUM('Feb 26'!$L13:$O13) -> 14 | L13: 5 | M13: 5 | N13: 3 | O13: 1
A14: SWSH | B14: 44228 | C14: Shining Fates | D14: 512 | E14: 375 | F14: 431 | G14: ='Feb 26'!$D14/E14 -> 1.3653333 | I14: ='Feb 26'!$F14/'Feb 26'!$E14 -> 1.1493333 | K14: =SUM('Feb 26'!$L14:$O14) -> 0
A15: SWSH | B15: 44348 | C15: Chilling Reign | D15: 550 | E15: 1050 | F15: 470 | G15: ='Feb 26'!$D15/E15 -> 0.52380952 | H15: Fair Value | I15: ='Feb 26'!$F15/'Feb 26'!$E15 -> 0.44761905 | K15: =SUM('Feb 26'!$L15:$O15) -> 0
A16: SWSH | B16: 44409 | C16: Evolving Skies | D16: 1750 | E16: 3050 | F16: 2096 | G16: ='Feb 26'!$D16/E16 -> 0.57377049 | H16: BLUE CHIP (Core Hold) | I16: ='Feb 26'!$F16/'Feb 26'!$E16 -> 0.68721311 | J16: Long-Term OOP | K16: =SUM('Feb 26'!$L16:$O16) -> 20 | L16: 5 | M16: 5 | N16: 5 | O16: 5
A17: SWSH | B17: 44470 | C17: Celebrations 25th | D17: 1120 | E17: 560 | F17: 289 | G17: ='Feb 26'!$D17/E17 -> 2 | I17: ='Feb 26'!$F17/'Feb 26'!$E17 -> 0.51607143 | K17: =SUM('Feb 26'!$L17:$O17) -> 0
A18: SWSH | B18: 44501 | C18: Fusion Strike | D18: 795 | E18: 1150 | F18: 900 | G18: ='Feb 26'!$D18/E18 -> 0.69130435 | H18: Hold / Take Profits | I18: ='Feb 26'!$F18/'Feb 26'!$E18 -> 0.7826087 | K18: =SUM('Feb 26'!$L18:$O18) -> 0
A19: SWSH | B19: 44593 | C19: Brilliant Stars | D19: 419 | E19: 490 | F19: 262 | G19: ='Feb 26'!$D19/E19 -> 0.85510204 | I19: ='Feb 26'!$F19/'Feb 26'!$E19 -> 0.53469388 | K19: =SUM('Feb 26'!$L19:$O19) -> 0
A20: SWSH | B20: 44682 | C20: Astral Radiance | D20: 285 | E20: 742 | F20: 230 | G20: ='Feb 26'!$D20/E20 -> 0.38409703 | I20: ='Feb 26'!$F20/'Feb 26'!$E20 -> 0.30997305 | K20: =SUM('Feb 26'!$L20:$O20) -> 0
A21: SWSH | B21: 44805 | C21: Lost Origin | D21: 521 | E21: 816 | F21: 621 | G21: ='Feb 26'!$D21/E21 -> 0.63848039 | I21: ='Feb 26'!$F21/'Feb 26'!$E21 -> 0.76102941 | K21: =SUM('Feb 26'!$L21:$O21) -> 0
A22: SWSH | B22: 44866 | C22: Silver Tempest | D22: 350 | E22: 540 | F22: 300 | G22: ='Feb 26'!$D22/E22 -> 0.64814815 | I22: ='Feb 26'!$F22/'Feb 26'!$E22 -> 0.55555556 | K22: =SUM('Feb 26'!$L22:$O22) -> 0
A23: SWSH | B23: 44927 | C23: Crown Zenith | D23: 984 | E23: 1720 | F23: 514 | G23: ='Feb 26'!$D23/E23 -> 0.57209302 | I23: ='Feb 26'!$F23/'Feb 26'!$E23 -> 0.29883721 | K23: =SUM('Feb 26'!$L23:$O23) -> 0
A24: S&V | B24: 44986 | C24: S&V Base set | D24: 198 | E24: 429 | F24: 90 | G24: ='Feb 26'!$D24/E24 -> 0.46153846 | I24: ='Feb 26'!$F24/'Feb 26'!$E24 -> 0.20979021 | J24: Printing Till Sprint 2026 | K24: =SUM('Feb 26'!$L24:$O24) -> 0
A25: S&V | B25: 45078 | C25: Paldea Evolved | D25: 320 | E25: 960 | F25: 300 | G25: ='Feb 26'!$D25/E25 -> 0.33333333 | I25: ='Feb 26'!$F25/'Feb 26'!$E25 -> 0.3125 | J25: Printing Till Sprint 2026 | K25: =SUM('Feb 26'!$L25:$O25) -> 4 | L25: 4
A26: S&V | B26: 45139 | C26: Obsidian Flames | D26: 110 | E26: 266 | F26: 97.92 | G26: ='Feb 26'!$D26/E26 -> 0.41353383 | H26: AVOID (Peak Hype) | I26: ='Feb 26'!$F26/'Feb 26'!$E26 -> 0.3681203 | J26: Printing Till Sprint 2026 | K26: =SUM('Feb 26'!$L26:$O26) -> 0
A27: S&V | B27: 45170 | C27: 151 | D27: 520 | E27: 1053 | F27: 317 | G27: ='Feb 26'!$D27/E27 -> 0.49382716 | I27: ='Feb 26'!$F27/'Feb 26'!$E27 -> 0.30104463 | J27: Printing Till Sprint 2026 | K27: =SUM('Feb 26'!$L27:$O27) -> 0
A28: S&V | B28: 45231 | C28: Paradox Rift | D28: 189 | E28: 605 | F28: 106 | G28: ='Feb 26'!$D28/E28 -> 0.31239669 | H28: Value Sleeper | I28: ='Feb 26'!$F28/'Feb 26'!$E28 -> 0.17520661 | J28: Printing Till Sprint 2026 | K28: =SUM('Feb 26'!$L28:$O28) -> 4 | L28: 4
A29: S&V | B29: 45292 | C29: Paldean Fates | D29: 400 | E29: 1105 | F29: 785 | G29: ='Feb 26'!$D29/E29 -> 0.36199095 | I29: ='Feb 26'!$F29/'Feb 26'!$E29 -> 0.71040724 | J29: Printing Till Sprint 2026 | K29: =SUM('Feb 26'!$L29:$O29) -> 0
A30: S&V | B30: 45352 | C30: Temporal Forces | D30: 198 | E30: 585 | F30: 110 | G30: ='Feb 26'!$D30/E30 -> 0.33846154 | I30: ='Feb 26'!$F30/'Feb 26'!$E30 -> 0.18803419 | J30: In Print | K30: =SUM('Feb 26'!$L30:$O30) -> 4 | L30: 4
A31: S&V | B31: 45413 | C31: Twilight Masquerade | D31: 125 | E31: 717 | F31: 321 | G31: ='Feb 26'!$D31/E31 -> 0.17433752 | H31: Neutral | I31: ='Feb 26'!$F31/'Feb 26'!$E31 -> 0.44769874 | J31: In Print | K31: =SUM('Feb 26'!$L31:$O31) -> 2 | L31: 2
A32: S&V | B32: 45505 | C32: Shrouded Fable | D32: 259.25 | E32: 305 | F32: 123 | G32: ='Feb 26'!$D32/E32 -> 0.85 | I32: ='Feb 26'!$F32/'Feb 26'!$E32 -> 0.40327869 | J32: In Print | K32: =SUM('Feb 26'!$L32:$O32) -> 0
A33: S&V | B33: 45536 | C33: Stellar Crown | D33: 110 | E33: 165 | F33: 122 | G33: ='Feb 26'!$D33/E33 -> 0.66666667 | H33: Overvalued (Avoid) | I33: ='Feb 26'!$F33/'Feb 26'!$E33 -> 0.73939394 | J33: In Print | K33: =SUM('Feb 26'!$L33:$O33) -> 0
A34: S&V | B34: 45597 | C34: Surging Sparks | D34: 200 | E34: 725 | F34: 372 | G34: ='Feb 26'!$D34/E34 -> 0.27586207 | H34: Buy on Dips | I34: ='Feb 26'!$F34/'Feb 26'!$E34 -> 0.51310345 | J34: In Print | K34: =SUM('Feb 26'!$L34:$O34) -> 3 | L34: 3
A35: S&V | B35: 45658 | C35: Prismatic Evolutions | D35: 405 | E35: 4095 | F35: 1550 | G35: ='Feb 26'!$D35/E35 -> 0.098901099 | I35: ='Feb 26'!$F35/'Feb 26'!$E35 -> 0.37851038 | K35: =SUM('Feb 26'!$L35:$O35) -> 14 | L35: 2 | M35: 2 | N35: 5 | O35: 5
A36: S&V | B36: 45717 | C36: Journey Together | D36: 180 | E36: 400 | F36: 182 | G36: ='Feb 26'!$D36/E36 -> 0.45 | I36: ='Feb 26'!$F36/'Feb 26'!$E36 -> 0.455 | K36: =SUM('Feb 26'!$L36:$O36) -> 0
A37: S&V | B37: 45778 | C37: Destined Rivals | D37: 310 | E37: 1010 | F37: 550 | G37: ='Feb 26'!$D37/E37 -> 0.30693069 | H37: ACCUMULATE | I37: ='Feb 26'!$F37/'Feb 26'!$E37 -> 0.54455446 | K37: =SUM('Feb 26'!$L37:$O37) -> 19 | L37: 4 | M37: 5 | N37: 5 | O37: 5
A38: S&V | B38: 45839 | C38: White Flare | D38: 312 | E38: 1550 | F38: 561.89 | G38: ='Feb 26'!$D38/E38 -> 0.20129032 | I38: ='Feb 26'!$F38/'Feb 26'!$E38 -> 0.36250968 | K38: =SUM('Feb 26'!$L38:$O38) -> 1 | L38: 1
A39: S&V | B39: 45839 | C39: Black Bolt | D39: 408 | E39: 1972 | F39: 938 | G39: ='Feb 26'!$D39/E39 -> 0.20689655 | I39: ='Feb 26'!$F39/'Feb 26'!$E39 -> 0.47565923 | K39: =SUM('Feb 26'!$L39:$O39) -> 1 | L39: 1
A40: S&V | B40: 45901 | C40: Mega Evolution | D40: 155 | E40: 1720 | F40: 450 | G40: ='Feb 26'!$D40/E40 -> 0.090116279 | H40: STRONG BUY (Deep Value) | I40: ='Feb 26'!$F40/'Feb 26'!$E40 -> 0.26162791 | K40: =SUM('Feb 26'!$L40:$O40) -> 1 | L40: 1
...

Sheet Selling Individual Cards
A1: Card Name | B1: Raw Price | C1: PSA 10 Price | D1: Price Increase | E1: Total Graded Copies | F1: Total 10 Copies | G1: 10-Rate (Pop %) | H1: Mascot? (Charizard, Pikachu, Umbreon, Gengar, Rayquaza, Special Illustration Rare (SIR) Trainers (like Lillie or Dawn), Competitive play cards)
A2: 2022 JP Origin Form Giratina - VSTAR Universe | B2: 108 | C2: 162 | D2: =C2/B2 -> 1.5 | E2: 28798 | F2: 27000 | G2: =F2/E2 -> 0.93756511
A3: 2022 JP Origin Form Dialga - VSTAR Universe | B3: 47 | C3: 100 | D3: =C3/B3 -> 2.1276596 | E3: 19397 | F3: 18000 | G3: =F3/E3 -> 0.92797855
A4: 2022 JP Origin Form Arceus - VSTAR Universe | B4: 75 | C4: 127 | D4: =C4/B4 -> 1.6933333 | E4: 23750 | F4: 22000 | G4: =F4/E4 -> 0.92631579
A5: 2022 JP Origin Form Palkia - VSTAR Universe | B5: 40 | C5: 95 | D5: =C5/B5 -> 2.375 | E5: 19689 | F5: 18000 | G5: =F5/E5 -> 0.91421606
A6: 2023 JP Charizard ex - SAR | B6: 138 | C6: 250 | D6: =C6/B6 -> 1.8115942 | E6: 23358 | F6: 21000 | G6: =F6/E6 -> 0.89904958
A7: 2023 JP Charizard ex - SAR | B7: 93 | C7: 240 | D7: =C7/B7 -> 2.5806452 | E7: 19368 | F7: 17000 | G7: =F7/E7 -> 0.87773647
A8: 2023 JP Venusaur ex - SAR | B8: 60 | C8: 88 | D8: =C8/B8 -> 1.4666667 | E8: 22917 | F8: 20000 | G8: =F8/E8 -> 0.87271458
A9: 2021 JP Vaporeon V - Eevee Heroes | B9: 72 | C9: 132 | D9: =C9/B9 -> 1.8333333 | E9: 10661 | F9: 9263 | G9: =F9/E9 -> 0.86886784
A10: 2022 JP Charizard V - VSTAR Universe | B10: 22 | C10: 66.25 | D10: =C10/B10 -> 3.0113636 | E10: 21327 | F10: 18000 | G10: =F10/E10 -> 0.84400056
A11: 2023 JP Venusaur - Classic Collection | B11: 21 | C11: 60 | D11: =C11/B11 -> 2.8571429 | E11: 7096 | F11: 5657 | G11: =F11/E11 -> 0.7972097
A12: 2023 JP Charizard - Classic Collection | B12: 108 | C12: 260 | D12: =C12/B12 -> 2.4074074 | E12: 11361 | F12: 9000 | G12: =F12/E12 -> 0.79218379
A13: 2024 JP Eevee - Art Rare | B13: 17 | C13: 55 | D13: =C13/B13 -> 3.2352941 | E13: 28325 | F13: 25000 | G13: =F13/E13 -> 0.88261253
... A16: 2021 JP Rayquaza VMAX - VMAX Climax | B16: 47 | C16: 120 | D16: =C16/B16 -> 2.5531915 | E16: 8926 | F16: 7777 | G16: =F16/E16 -> 0.87127493
